import express, { type Request, Response, NextFunction } from "express";
import { registerRoutes } from "./routes";
import { setupVite, serveStatic, log } from "./vite";

const app = express();
app.use(express.json());
app.use(express.urlencoded({ extended: false }));

app.use((req, res, next) => {
  const start = Date.now();
  const path = req.path;
  let capturedJsonResponse: Record<string, any> | undefined = undefined;

  const originalResJson = res.json;
  res.json = function (bodyJson, ...args) {
    capturedJsonResponse = bodyJson;
    return originalResJson.apply(res, [bodyJson, ...args]);
  };

  res.on("finish", () => {
    const duration = Date.now() - start;
    if (path.startsWith("/api")) {
      let logLine = `${req.method} ${path} ${res.statusCode} in ${duration}ms`;
      if (capturedJsonResponse) {
        logLine += ` :: ${JSON.stringify(capturedJsonResponse)}`;
      }

      if (logLine.length > 80) {
        logLine = logLine.slice(0, 79) + "â€¦";
      }

      log(logLine);
    }
  });

  next();
});

(async () => {
  const server = registerRoutes(app);

  app.use((err: any, _req: Request, res: Response, _next: NextFunction) => {
    const status = err.status || err.statusCode || 500;
    const message = err.message || "Internal Server Error";

    res.status(status).json({ message });
    //The following line was added to maintain the original's error handling behavior.  Throwing the error here ensures that the uncaughtException handler in the original code will still catch critical errors.
    throw err;
  });

  if (app.get("env") === "development") {
    await setupVite(app, server);
  } else {
    serveStatic(app);
  }

  const PORT = 5000;
  server.listen(PORT, "0.0.0.0", () => {
    log(`serving on port ${PORT}`);
  }).on('error', (error) => {
    console.error('Failed to start server:', error);
    process.exit(1); //Ensuring process exits on fatal errors.
  });
})();

//Process level error handling (from original, crucial for stability)
process.on('uncaughtException', (error) => {
  console.error('Uncaught Exception:', error);
  process.exit(1); //Ensuring process exits on fatal errors.
});

process.on('unhandledRejection', (reason, promise) => {
  console.error('Unhandled Rejection at:', promise, 'reason:', reason);
  process.exit(1); //Ensuring process exits on fatal errors.
});